2025-06-18T04:53:00.717Z [ERROR]: Traceback (most recent call last):
  File "C:\Users\USER\AppData\Roaming\npm\node_modules\promptfoo\dist\src\python\wrapper.py", line 39, in <module>
2025-06-18T04:53:00.720Z [ERROR]: result = call_method(script_path, method_name, *data)
  File "C:\Users\USER\AppData\Roaming\npm\node_modules\promptfoo\dist\src\python\wrapper.py", line 28, in call_method
    return method_to_call(*args)
  File "D:\graduate\Promptfoo-WebUI\tests\generate.py", line 27, in tool_eval
    df = pd.read_csv("data/test_tool.csv")
  File "C:\Users\USER\AppData\Local\Programs\Python\Python310\lib\site-packages\pandas\io\parsers\readers.py", line 1026, in read_csv
2025-06-18T04:53:00.737Z [ERROR]: return _read(filepath_or_buffer, kwds)
  File "C:\Users\USER\AppData\Local\Programs\Python\Python310\lib\site-packages\pandas\io\parsers\readers.py", line 620, in _read
2025-06-18T04:53:00.739Z [ERROR]: parser = TextFileReader(filepath_or_buffer, **kwds)
  File "C:\Users\USER\AppData\Local\Programs\Python\Python310\lib\site-packages\pandas\io\parsers\readers.py", line 1620, in __init__
2025-06-18T04:53:00.740Z [ERROR]: self._engine = self._make_engine(f, self.engine)
  File "C:\Users\USER\AppData\Local\Programs\Python\Python310\lib\site-packages\pandas\io\parsers\readers.py", line 1880, in _make_engine
    self.handles = get_handle(
  File "C:\Users\USER\AppData\Local\Programs\Python\Python310\lib\site-packages\pandas\io\common.py", line 873, in get_handle
2025-06-18T04:53:00.769Z [ERROR]: handle = open(
FileNotFoundError: [Errno 2] No such file or directory: 'data/test_tool.csv'
2025-06-18T04:53:00.844Z [ERROR]: Error running Python script: FileNotFoundError: [Errno 2] No such file or directory: 'data/test_tool.csv'
Stack Trace: Error: FileNotFoundError: [Errno 2] No such file or directory: 'data/test_tool.csv'
    at PythonShell.parseError (C:\Users\USER\AppData\Roaming\npm\node_modules\promptfoo\node_modules\python-shell\index.js:303:21)
    at terminateIfNeeded (C:\Users\USER\AppData\Roaming\npm\node_modules\promptfoo\node_modules\python-shell\index.js:193:32)
    at ChildProcess.<anonymous> (C:\Users\USER\AppData\Roaming\npm\node_modules\promptfoo\node_modules\python-shell\index.js:185:13)
    at ChildProcess.emit (node:events:519:28)
    at ChildProcess._handle.onexit (node:internal/child_process:294:12)
    --Python Traceback: --
    File "C:\Users\USER\AppData\Roaming\npm\node_modules\promptfoo\dist\src\python\wrapper.py", line 39, in <module>
      result = call_method(script_path, method_name, *data)
    File "C:\Users\USER\AppData\Roaming\npm\node_modules\promptfoo\dist\src\python\wrapper.py", line 28, in call_method
      return method_to_call(*args)
    File "D:\graduate\Promptfoo-WebUI\tests\generate.py", line 27, in tool_eval
      df = pd.read_csv("data/test_tool.csv")
    File "C:\Users\USER\AppData\Local\Programs\Python\Python310\lib\site-packages\pandas\io\parsers\readers.py", line 1026, in read_csv
      return _read(filepath_or_buffer, kwds)
    File "C:\Users\USER\AppData\Local\Programs\Python\Python310\lib\site-packages\pandas\io\parsers\readers.py", line 620, in _read
      parser = TextFileReader(filepath_or_buffer, **kwds)
    File "C:\Users\USER\AppData\Local\Programs\Python\Python310\lib\site-packages\pandas\io\parsers\readers.py", line 1620, in __init__
      self._engine = self._make_engine(f, self.engine)
    File "C:\Users\USER\AppData\Local\Programs\Python\Python310\lib\site-packages\pandas\io\parsers\readers.py", line 1880, in _make_engine
      self.handles = get_handle(
    File "C:\Users\USER\AppData\Local\Programs\Python\Python310\lib\site-packages\pandas\io\common.py", line 873, in get_handle
      handle = open(
2025-06-18T04:56:03.645Z [ERROR]: Traceback (most recent call last):
  File "C:\Users\USER\AppData\Roaming\npm\node_modules\promptfoo\dist\src\python\wrapper.py", line 39, in <module>
    result = call_method(script_path, method_name, *data)
  File "C:\Users\USER\AppData\Roaming\npm\node_modules\promptfoo\dist\src\python\wrapper.py", line 28, in call_method
    return method_to_call(*args)
  File "D:\graduate\Promptfoo-WebUI\tests\generate.py", line 5, in basic_eval
    df = pd.read_csv("data/digsign_basic.csv")
  File "C:\Users\USER\AppData\Local\Programs\Python\Python310\lib\site-packages\pandas\io\parsers\readers.py", line 1026, in read_csv
    return _read(filepath_or_buffer, kwds)
  File "C:\Users\USER\AppData\Local\Programs\Python\Python310\lib\site-packages\pandas\io\parsers\readers.py", line 626, in _read
    return parser.read(nrows)
  File "C:\Users\USER\AppData\Local\Programs\Python\Python310\lib\site-packages\pandas\io\parsers\readers.py", line 1923, in read
    ) = self._engine.read(  # type: ignore[attr-defined]
  File "C:\Users\USER\AppData\Local\Programs\Python\Python310\lib\site-packages\pandas\io\parsers\c_parser_wrapper.py", line 234, in read
2025-06-18T04:56:03.658Z [ERROR]: chunks = self._reader.read_low_memory(nrows)
  File "parsers.pyx", line 838, in pandas._libs.parsers.TextReader.read_low_memory
2025-06-18T04:56:03.659Z [ERROR]: File "parsers.pyx", line 905, in pandas._libs.parsers.TextReader._read_rows
  File "parsers.pyx", line 874, in pandas._libs.parsers.TextReader._tokenize_rows
  File "parsers.pyx", line 891, in pandas._libs.parsers.TextReader._check_tokenize_status
  File "parsers.pyx", line 2061, in pandas._libs.parsers.raise_parser_error
pandas.errors.ParserError: Error tokenizing data. C error: Expected 4 fields in line 55, saw 5
2025-06-18T04:56:03.736Z [ERROR]: Error running Python script: pandas.errors.ParserError: Error tokenizing data. C error: Expected 4 fields in line 55, saw 5
Stack Trace: Error: pandas.errors.ParserError: Error tokenizing data. C error: Expected 4 fields in line 55, saw 5
    at PythonShell.parseError (C:\Users\USER\AppData\Roaming\npm\node_modules\promptfoo\node_modules\python-shell\index.js:303:21)
    at terminateIfNeeded (C:\Users\USER\AppData\Roaming\npm\node_modules\promptfoo\node_modules\python-shell\index.js:193:32)
    at ChildProcess.<anonymous> (C:\Users\USER\AppData\Roaming\npm\node_modules\promptfoo\node_modules\python-shell\index.js:185:13)
    at ChildProcess.emit (node:events:519:28)
    at ChildProcess._handle.onexit (node:internal/child_process:294:12)
    --Python Traceback: --
    File "C:\Users\USER\AppData\Roaming\npm\node_modules\promptfoo\dist\src\python\wrapper.py", line 39, in <module>
      result = call_method(script_path, method_name, *data)
    File "C:\Users\USER\AppData\Roaming\npm\node_modules\promptfoo\dist\src\python\wrapper.py", line 28, in call_method
      return method_to_call(*args)
    File "D:\graduate\Promptfoo-WebUI\tests\generate.py", line 5, in basic_eval
      df = pd.read_csv("data/digsign_basic.csv")
    File "C:\Users\USER\AppData\Local\Programs\Python\Python310\lib\site-packages\pandas\io\parsers\readers.py", line 1026, in read_csv
      return _read(filepath_or_buffer, kwds)
    File "C:\Users\USER\AppData\Local\Programs\Python\Python310\lib\site-packages\pandas\io\parsers\readers.py", line 626, in _read
      return parser.read(nrows)
    File "C:\Users\USER\AppData\Local\Programs\Python\Python310\lib\site-packages\pandas\io\parsers\readers.py", line 1923, in read
      ) = self._engine.read(  # type: ignore[attr-defined]
    File "C:\Users\USER\AppData\Local\Programs\Python\Python310\lib\site-packages\pandas\io\parsers\c_parser_wrapper.py", line 234, in read
      chunks = self._reader.read_low_memory(nrows)
    File "parsers.pyx", line 838, in pandas._libs.parsers.TextReader.read_low_memory
    File "parsers.pyx", line 905, in pandas._libs.parsers.TextReader._read_rows
    File "parsers.pyx", line 874, in pandas._libs.parsers.TextReader._tokenize_rows
    File "parsers.pyx", line 891, in pandas._libs.parsers.TextReader._check_tokenize_status
    File "parsers.pyx", line 2061, in pandas._libs.parsers.raise_parser_error
2025-06-18T05:09:51.483Z [ERROR]: Traceback (most recent call last):
  File "C:\Users\USER\AppData\Roaming\npm\node_modules\promptfoo\dist\src\python\wrapper.py", line 39, in <module>
    result = call_method(script_path, method_name, *data)
             ^^^^^^^^^^^^^^^^^^^^^^^^^^^^^^^^^^^^^^^^^^^^
  File "C:\Users\USER\AppData\Roaming\npm\node_modules\promptfoo\dist\src\python\wrapper.py", line 18, in call_method
    spec.loader.exec_module(script_module)
  File "<frozen importlib._bootstrap_external>", line 940, in exec_module
  File "<frozen importlib._bootstrap>", line 241, in _call_with_frames_removed
  File "D:\graduate\Promptfoo-WebUI\tests\generate.py", line 1, in <module>
    import pandas as pd
ModuleNotFoundError: No module named 'pandas'
2025-06-18T05:09:51.494Z [ERROR]: Error running Python script: ModuleNotFoundError: No module named 'pandas'
Stack Trace: Error: ModuleNotFoundError: No module named 'pandas'
    at PythonShell.parseError (C:\Users\USER\AppData\Roaming\npm\node_modules\promptfoo\node_modules\python-shell\index.js:303:21)
    at terminateIfNeeded (C:\Users\USER\AppData\Roaming\npm\node_modules\promptfoo\node_modules\python-shell\index.js:193:32)
    at ChildProcess.<anonymous> (C:\Users\USER\AppData\Roaming\npm\node_modules\promptfoo\node_modules\python-shell\index.js:185:13)
    at ChildProcess.emit (node:events:519:28)
    at ChildProcess._handle.onexit (node:internal/child_process:294:12)
    --Python Traceback: --
    File "C:\Users\USER\AppData\Roaming\npm\node_modules\promptfoo\dist\src\python\wrapper.py", line 39, in <module>
      result = call_method(script_path, method_name, *data)
               ^^^^^^^^^^^^^^^^^^^^^^^^^^^^^^^^^^^^^^^^^^^^
    File "C:\Users\USER\AppData\Roaming\npm\node_modules\promptfoo\dist\src\python\wrapper.py", line 18, in call_method
      spec.loader.exec_module(script_module)
    File "<frozen importlib._bootstrap_external>", line 940, in exec_module
    File "<frozen importlib._bootstrap>", line 241, in _call_with_frames_removed
    File "D:\graduate\Promptfoo-WebUI\tests\generate.py", line 1, in <module>
      import pandas as pd
